[2020-11-01 18:55:08,349] {taskinstance.py:670} INFO - Dependencies all met for <TaskInstance: S3_task.upload_file_to_S3 2020-11-01T01:00:00+00:00 [queued]>
[2020-11-01 18:55:08,431] {taskinstance.py:670} INFO - Dependencies all met for <TaskInstance: S3_task.upload_file_to_S3 2020-11-01T01:00:00+00:00 [queued]>
[2020-11-01 18:55:08,431] {taskinstance.py:880} INFO - 
--------------------------------------------------------------------------------
[2020-11-01 18:55:08,432] {taskinstance.py:881} INFO - Starting attempt 2 of 4
[2020-11-01 18:55:08,432] {taskinstance.py:882} INFO - 
--------------------------------------------------------------------------------
[2020-11-01 18:55:08,449] {taskinstance.py:901} INFO - Executing <Task(PythonOperator): upload_file_to_S3> on 2020-11-01T01:00:00+00:00
[2020-11-01 18:55:08,454] {standard_task_runner.py:54} INFO - Started process 25978 to run task
[2020-11-01 18:55:08,533] {standard_task_runner.py:77} INFO - Running: ['airflow', 'run', 'S3_task', 'upload_file_to_S3', '2020-11-01T01:00:00+00:00', '--job_id', '24', '--pool', 'default_pool', '--raw', '-sd', '/home/akorede/Documents/airflow_sandbox/airflow/dags/s3_dag.py', '--cfg_path', '/tmp/tmporsj03jr']
[2020-11-01 18:55:08,538] {standard_task_runner.py:78} INFO - Job 24: Subtask upload_file_to_S3
[2020-11-01 18:55:08,672] {logging_mixin.py:112} INFO - Running %s on host %s <TaskInstance: S3_task.upload_file_to_S3 2020-11-01T01:00:00+00:00 [running]> akorede-VirtualBox
[2020-11-01 18:55:10,333] {taskinstance.py:1150} ERROR - The key mycsv.csv already exists.
Traceback (most recent call last):
  File "/home/akorede/.local/lib/python3.6/site-packages/airflow/models/taskinstance.py", line 984, in _run_raw_task
    result = task_copy.execute(context=context)
  File "/home/akorede/.local/lib/python3.6/site-packages/airflow/operators/python_operator.py", line 113, in execute
    return_value = self.execute_callable()
  File "/home/akorede/.local/lib/python3.6/site-packages/airflow/operators/python_operator.py", line 118, in execute_callable
    return self.python_callable(*self.op_args, **self.op_kwargs)
  File "/home/akorede/Documents/airflow_sandbox/airflow/dags/s3_dag.py", line 50, in upload_file_to_S3_with_hook
    hook.load_file(filename, key, bucket_name)
  File "/home/akorede/.local/lib/python3.6/site-packages/airflow/hooks/S3_hook.py", line 358, in load_file
    raise ValueError("The key {key} already exists.".format(key=key))
ValueError: The key mycsv.csv already exists.
[2020-11-01 18:55:10,344] {taskinstance.py:1194} INFO - Marking task as UP_FOR_RETRY. dag_id=S3_task, task_id=upload_file_to_S3, execution_date=20201101T010000, start_date=20201101T175508, end_date=20201101T175510
[2020-11-01 18:55:13,292] {local_task_job.py:102} INFO - Task exited with return code 1
