[2020-11-01 19:04:20,555] {taskinstance.py:670} INFO - Dependencies all met for <TaskInstance: S3_task.upload_file_to_S3 2020-11-01T09:00:00+00:00 [queued]>
[2020-11-01 19:04:20,602] {taskinstance.py:670} INFO - Dependencies all met for <TaskInstance: S3_task.upload_file_to_S3 2020-11-01T09:00:00+00:00 [queued]>
[2020-11-01 19:04:20,602] {taskinstance.py:880} INFO - 
--------------------------------------------------------------------------------
[2020-11-01 19:04:20,602] {taskinstance.py:881} INFO - Starting attempt 4 of 4
[2020-11-01 19:04:20,602] {taskinstance.py:882} INFO - 
--------------------------------------------------------------------------------
[2020-11-01 19:04:20,616] {taskinstance.py:901} INFO - Executing <Task(PythonOperator): upload_file_to_S3> on 2020-11-01T09:00:00+00:00
[2020-11-01 19:04:20,621] {standard_task_runner.py:54} INFO - Started process 29337 to run task
[2020-11-01 19:04:20,682] {standard_task_runner.py:77} INFO - Running: ['airflow', 'run', 'S3_task', 'upload_file_to_S3', '2020-11-01T09:00:00+00:00', '--job_id', '78', '--pool', 'default_pool', '--raw', '-sd', '/home/akorede/Documents/airflow_sandbox/airflow/dags/s3_dag.py', '--cfg_path', '/tmp/tmpg4y_pbqz']
[2020-11-01 19:04:20,686] {standard_task_runner.py:78} INFO - Job 78: Subtask upload_file_to_S3
[2020-11-01 19:04:20,764] {logging_mixin.py:112} INFO - Running %s on host %s <TaskInstance: S3_task.upload_file_to_S3 2020-11-01T09:00:00+00:00 [running]> akorede-VirtualBox
[2020-11-01 19:04:22,354] {taskinstance.py:1150} ERROR - The key mycsv.csv already exists.
Traceback (most recent call last):
  File "/home/akorede/.local/lib/python3.6/site-packages/airflow/models/taskinstance.py", line 984, in _run_raw_task
    result = task_copy.execute(context=context)
  File "/home/akorede/.local/lib/python3.6/site-packages/airflow/operators/python_operator.py", line 113, in execute
    return_value = self.execute_callable()
  File "/home/akorede/.local/lib/python3.6/site-packages/airflow/operators/python_operator.py", line 118, in execute_callable
    return self.python_callable(*self.op_args, **self.op_kwargs)
  File "/home/akorede/Documents/airflow_sandbox/airflow/dags/s3_dag.py", line 50, in upload_file_to_S3_with_hook
    hook.load_file(filename, key, bucket_name)
  File "/home/akorede/.local/lib/python3.6/site-packages/airflow/hooks/S3_hook.py", line 358, in load_file
    raise ValueError("The key {key} already exists.".format(key=key))
ValueError: The key mycsv.csv already exists.
[2020-11-01 19:04:22,359] {taskinstance.py:1194} INFO - Marking task as FAILED. dag_id=S3_task, task_id=upload_file_to_S3, execution_date=20201101T090000, start_date=20201101T180420, end_date=20201101T180422
[2020-11-01 19:04:25,518] {local_task_job.py:102} INFO - Task exited with return code 1
