[2020-11-01 23:33:08,522] {taskinstance.py:670} INFO - Dependencies all met for <TaskInstance: S3_task.upload_file_to_S3 2020-11-01T21:00:00+00:00 [queued]>
[2020-11-01 23:33:08,563] {taskinstance.py:670} INFO - Dependencies all met for <TaskInstance: S3_task.upload_file_to_S3 2020-11-01T21:00:00+00:00 [queued]>
[2020-11-01 23:33:08,563] {taskinstance.py:880} INFO - 
--------------------------------------------------------------------------------
[2020-11-01 23:33:08,563] {taskinstance.py:881} INFO - Starting attempt 4 of 4
[2020-11-01 23:33:08,564] {taskinstance.py:882} INFO - 
--------------------------------------------------------------------------------
[2020-11-01 23:33:08,576] {taskinstance.py:901} INFO - Executing <Task(PythonOperator): upload_file_to_S3> on 2020-11-01T21:00:00+00:00
[2020-11-01 23:33:08,581] {standard_task_runner.py:54} INFO - Started process 4119 to run task
[2020-11-01 23:33:08,633] {standard_task_runner.py:77} INFO - Running: ['airflow', 'run', 'S3_task', 'upload_file_to_S3', '2020-11-01T21:00:00+00:00', '--job_id', '134', '--pool', 'default_pool', '--raw', '-sd', '/home/akorede/Documents/airflow_sandbox/airflow/dags/s3_dag.py', '--cfg_path', '/tmp/tmpom3697vf']
[2020-11-01 23:33:08,638] {standard_task_runner.py:78} INFO - Job 134: Subtask upload_file_to_S3
[2020-11-01 23:33:08,707] {logging_mixin.py:112} INFO - Running %s on host %s <TaskInstance: S3_task.upload_file_to_S3 2020-11-01T21:00:00+00:00 [running]> akorede-VirtualBox
[2020-11-01 23:33:10,058] {taskinstance.py:1150} ERROR - name 'data' is not defined
Traceback (most recent call last):
  File "/home/akorede/.local/lib/python3.6/site-packages/airflow/models/taskinstance.py", line 984, in _run_raw_task
    result = task_copy.execute(context=context)
  File "/home/akorede/.local/lib/python3.6/site-packages/airflow/operators/python_operator.py", line 113, in execute
    return_value = self.execute_callable()
  File "/home/akorede/.local/lib/python3.6/site-packages/airflow/operators/python_operator.py", line 118, in execute_callable
    return self.python_callable(*self.op_args, **self.op_kwargs)
  File "/home/akorede/Documents/airflow_sandbox/airflow/dags/s3_dag.py", line 65, in upload_file_to_S3_with_hook
    key.download_fileobj(data)
NameError: name 'data' is not defined
[2020-11-01 23:33:10,062] {taskinstance.py:1194} INFO - Marking task as FAILED. dag_id=S3_task, task_id=upload_file_to_S3, execution_date=20201101T210000, start_date=20201101T223308, end_date=20201101T223310
[2020-11-01 23:33:13,496] {local_task_job.py:102} INFO - Task exited with return code 1
