[2020-11-02 04:23:05,193] {taskinstance.py:670} INFO - Dependencies all met for <TaskInstance: S3_task.get_new_json 2020-11-02T03:22:27.937988+00:00 [queued]>
[2020-11-02 04:23:05,240] {taskinstance.py:670} INFO - Dependencies all met for <TaskInstance: S3_task.get_new_json 2020-11-02T03:22:27.937988+00:00 [queued]>
[2020-11-02 04:23:05,240] {taskinstance.py:880} INFO - 
--------------------------------------------------------------------------------
[2020-11-02 04:23:05,240] {taskinstance.py:881} INFO - Starting attempt 1 of 4
[2020-11-02 04:23:05,240] {taskinstance.py:882} INFO - 
--------------------------------------------------------------------------------
[2020-11-02 04:23:05,265] {taskinstance.py:901} INFO - Executing <Task(S3KeySensor): get_new_json> on 2020-11-02T03:22:27.937988+00:00
[2020-11-02 04:23:05,269] {standard_task_runner.py:54} INFO - Started process 2928 to run task
[2020-11-02 04:23:05,350] {standard_task_runner.py:77} INFO - Running: ['airflow', 'run', 'S3_task', 'get_new_json', '2020-11-02T03:22:27.937988+00:00', '--job_id', '190', '--pool', 'default_pool', '--raw', '-sd', '/home/akorede/Documents/airflow_sandbox/airflow/dags/s3_dag.py', '--cfg_path', '/tmp/tmp0vpgiuo6']
[2020-11-02 04:23:05,353] {standard_task_runner.py:78} INFO - Job 190: Subtask get_new_json
[2020-11-02 04:23:05,426] {logging_mixin.py:112} INFO - Running %s on host %s <TaskInstance: S3_task.get_new_json 2020-11-02T03:22:27.937988+00:00 [running]> akorede-VirtualBox
[2020-11-02 04:23:05,474] {s3_key_sensor.py:88} INFO - Poking for key : s3://ypsource_bucket/s3//ypsource_bucket/ypsource.json
[2020-11-02 04:23:07,621] {taskinstance.py:1150} ERROR - Unable to locate credentials
Traceback (most recent call last):
  File "/home/akorede/.local/lib/python3.6/site-packages/airflow/models/taskinstance.py", line 984, in _run_raw_task
    result = task_copy.execute(context=context)
  File "/home/akorede/.local/lib/python3.6/site-packages/airflow/sensors/base_sensor_operator.py", line 107, in execute
    while not self.poke(context):
  File "/home/akorede/.local/lib/python3.6/site-packages/airflow/sensors/s3_key_sensor.py", line 93, in poke
    return hook.check_for_key(self.bucket_key, self.bucket_name)
  File "/home/akorede/.local/lib/python3.6/site-packages/airflow/hooks/S3_hook.py", line 206, in check_for_key
    self.get_conn().head_object(Bucket=bucket_name, Key=key)
  File "/home/akorede/.local/lib/python3.6/site-packages/botocore/client.py", line 357, in _api_call
    return self._make_api_call(operation_name, kwargs)
  File "/home/akorede/.local/lib/python3.6/site-packages/botocore/client.py", line 663, in _make_api_call
    operation_model, request_dict, request_context)
  File "/home/akorede/.local/lib/python3.6/site-packages/botocore/client.py", line 682, in _make_request
    return self._endpoint.make_request(operation_model, request_dict)
  File "/home/akorede/.local/lib/python3.6/site-packages/botocore/endpoint.py", line 102, in make_request
    return self._send_request(request_dict, operation_model)
  File "/home/akorede/.local/lib/python3.6/site-packages/botocore/endpoint.py", line 132, in _send_request
    request = self.create_request(request_dict, operation_model)
  File "/home/akorede/.local/lib/python3.6/site-packages/botocore/endpoint.py", line 116, in create_request
    operation_name=operation_model.name)
  File "/home/akorede/.local/lib/python3.6/site-packages/botocore/hooks.py", line 356, in emit
    return self._emitter.emit(aliased_event_name, **kwargs)
  File "/home/akorede/.local/lib/python3.6/site-packages/botocore/hooks.py", line 228, in emit
    return self._emit(event_name, kwargs)
  File "/home/akorede/.local/lib/python3.6/site-packages/botocore/hooks.py", line 211, in _emit
    response = handler(**kwargs)
  File "/home/akorede/.local/lib/python3.6/site-packages/botocore/signers.py", line 90, in handler
    return self.sign(operation_name, request)
  File "/home/akorede/.local/lib/python3.6/site-packages/botocore/signers.py", line 162, in sign
    auth.add_auth(request)
  File "/home/akorede/.local/lib/python3.6/site-packages/botocore/auth.py", line 357, in add_auth
    raise NoCredentialsError
botocore.exceptions.NoCredentialsError: Unable to locate credentials
[2020-11-02 04:23:07,625] {taskinstance.py:1194} INFO - Marking task as UP_FOR_RETRY. dag_id=S3_task, task_id=get_new_json, execution_date=20201102T032227, start_date=20201102T032305, end_date=20201102T032307
[2020-11-02 04:23:10,137] {local_task_job.py:102} INFO - Task exited with return code 1
